Traceback (most recent call last):
  File "/usr/local/python/3.10.13/lib/python3.10/site-packages/psutil/_pslinux.py", line 1714, in wrapper
    return fun(self, *args, **kwargs)
  File "/usr/local/python/3.10.13/lib/python3.10/site-packages/psutil/_common.py", line 497, in wrapper
    raise raise_from(err, None)
  File "<string>", line 3, in raise_from
  File "/usr/local/python/3.10.13/lib/python3.10/site-packages/psutil/_common.py", line 495, in wrapper
    return fun(self)
  File "/usr/local/python/3.10.13/lib/python3.10/site-packages/psutil/_pslinux.py", line 1777, in _parse_stat_file
    data = bcat("%s/%s/stat" % (self._procfs_path, self.pid))
  File "/usr/local/python/3.10.13/lib/python3.10/site-packages/psutil/_common.py", line 840, in bcat
    return cat(fname, fallback=fallback, _open=open_binary)
  File "/usr/local/python/3.10.13/lib/python3.10/site-packages/psutil/_common.py", line 828, in cat
    with _open(fname) as f:
  File "/usr/local/python/3.10.13/lib/python3.10/site-packages/psutil/_common.py", line 788, in open_binary
    return open(fname, "rb", buffering=FILE_READ_BUFFER_SIZE)
FileNotFoundError: [Errno 2] No such file or directory: '/proc/4615/stat'

During handling of the above exception, another exception occurred:

Traceback (most recent call last):
  File "/usr/local/python/3.10.13/lib/python3.10/site-packages/psutil/__init__.py", line 359, in _init
    self.create_time()
  File "/usr/local/python/3.10.13/lib/python3.10/site-packages/psutil/__init__.py", line 752, in create_time
    self._create_time = self._proc.create_time()
  File "/usr/local/python/3.10.13/lib/python3.10/site-packages/psutil/_pslinux.py", line 1714, in wrapper
    return fun(self, *args, **kwargs)
  File "/usr/local/python/3.10.13/lib/python3.10/site-packages/psutil/_pslinux.py", line 1945, in create_time
    ctime = float(self._parse_stat_file()['create_time'])
  File "/usr/local/python/3.10.13/lib/python3.10/site-packages/psutil/_pslinux.py", line 1723, in wrapper
    raise NoSuchProcess(self.pid, self._name)
psutil.NoSuchProcess: process no longer exists (pid=4615)

During handling of the above exception, another exception occurred:

Traceback (most recent call last):
  File "/home/codespace/.python/current/bin/airflow", line 8, in <module>
    sys.exit(main())
  File "/usr/local/python/3.10.13/lib/python3.10/site-packages/airflow/__main__.py", line 58, in main
    args.func(args)
  File "/usr/local/python/3.10.13/lib/python3.10/site-packages/airflow/cli/cli_config.py", line 49, in command
    return func(*args, **kwargs)
  File "/usr/local/python/3.10.13/lib/python3.10/site-packages/airflow/utils/cli.py", line 114, in wrapper
    return f(*args, **kwargs)
  File "/usr/local/python/3.10.13/lib/python3.10/site-packages/airflow/utils/providers_configuration_loader.py", line 55, in wrapped_function
    return func(*args, **kwargs)
  File "/usr/local/python/3.10.13/lib/python3.10/site-packages/airflow/cli/commands/webserver_command.py", line 485, in webserver
    run_command_with_daemon_option(
  File "/usr/local/python/3.10.13/lib/python3.10/site-packages/airflow/cli/commands/daemon_utils.py", line 80, in run_command_with_daemon_option
    callback()
  File "/usr/local/python/3.10.13/lib/python3.10/site-packages/airflow/cli/commands/webserver_command.py", line 488, in <lambda>
    callback=lambda: start_and_monitor_gunicorn(args),
  File "/usr/local/python/3.10.13/lib/python3.10/site-packages/airflow/cli/commands/webserver_command.py", line 471, in start_and_monitor_gunicorn
    gunicorn_master_proc = psutil.Process(gunicorn_master_proc_pid)
  File "/usr/local/python/3.10.13/lib/python3.10/site-packages/psutil/__init__.py", line 323, in __init__
    self._init(pid)
  File "/usr/local/python/3.10.13/lib/python3.10/site-packages/psutil/__init__.py", line 372, in _init
    raise NoSuchProcess(pid, msg=msg)
psutil.NoSuchProcess: process PID not found (pid=4615)
